Workbook
Name BritishStandard: Data!$E$45:$E$58
Name BS: Data!$E$45:$E$58
Name BS_7671: Data!$E$45:$E$58
Name Call_Out: Data!$W$4:$W$8
Name Callout: Data!$W$4:$W$8
Name Full_Inspection: Data!$U$4:$U$8
Name MEW: Data!$B$68:$B$77
Name Military: Data!$AC$14:$AC$15
Name NEC: Data!$D$45:$D$79
Name No: Data!$Q$4:$Q$5
Name O_M_Provider: Data!$AB$14:$AB$15
Name Re_Inspection: Data!$V$4:$V$8
Name Reference: [1]Data!$B$47:$B$49
Name Reference: Data!$B$47:$B$50
Name Task_Force_SAFE: Data!$AA$14:$AA$15
Name Yes: Data!$P$4:$P$5

Sheet Inspection Report
A1: =_xlfn.CONCAT(IF(B6="N/A","Inspection-Report_TFSAFE","Re-Inspection-Report_TFSAFE"),IF(D5="Callout","_Callout",""),IF(ISNUMBER(SEARCH("Callout",B6)),"_Callout",""),"_",B3,"_",B4,"_",D3,"_",TEXT(D2,"DD-MM-YY"),"_",Data!$V$31,Data!$V$32) -> Re-Inspection-Report_TFSAFE_R5SPE___00-01-00_0 | H1: =A1 -> Re-Inspection-Report_TFSAFE_R5SPE___00-01-00_0
A2: Base Location | B2: Camp Buehring | C2: Date: | H2: Base Location | I2: =B2 -> Camp Buehring | J2: Date: | K2: =D2 -> 0
A3: Base Code | B3: {=_xlfn.IFS(B2=Data!G3,Data!F3,B2=Data!G4,Data!F4,B2=Data!G5,Data!F5,B2=Data!G6,Data!F6,B2=Data!G7,Data!F7,B2=Data!G8,Data!F8,B2=Data!G9,Data!F9,B2=Data!G10,Data!F10,B2=Data!G11,Data!F11,B2=Data!G12,Data!F12,B2=Data!G13,Data!F13,B2=Data!G14,Data!F14,B2=Data!G15,Data!F15,B2=Data!G16,Data!F16,B2=Data!G17,Data!F17,B2=Data!G18,Data!F18,B2=Data!G19,Data!F19,B2=Data!G20,Data!F20,B2=Data!G21,Data!F21,B2=Data!G22,Data!F22,B2=Data!G23,Data!F23,B2=Data!G24,Data!F24,B2=Data!G25,Data!F25,B2=Data!G26,Data!F26,B2=Data!G27,Data!F27,B2=Data!G28,Data!F28,B2=Data!G29,Data!F29,B2=Data!G30,Data!F30,B2=Data!G31,Data!F31,B2=Data!G32,Data!F32,B2=Data!G33,Data!F33,B2=Data!G34,Data!F34,B2=Data!G35,Data!F35,B2=Data!G36,Data!F36,B2=Data!G37,Data!F37,B2=Data!G38,Data!F38,B2=Data!G39,Data!F39,B2=Data!G40,Data!F40,B2=Data!G41,Data!F41,B2=Data!G42,Data!F42,B2=Data!G43,Data!F43,B2=Data!G44,Data!F44,B2=Data!G45,Data!F45,B2=Data!G46,Data!F46,B2=Data!G47,Data!F47,B2=Data!G48,Data!F48,B2=Data!G49,Data!F49,B2=Data!G50,Data!F50,B2=Data!G51,Data!F51,B2=Data!G52,Data!F52,B2=Data!G53,Data!F53,B2=Data!G54,Data!F54,B2=Data!G55,Data!F55,B2=Data!G56,Data!F56,B2=Data!G57,Data!F57,B2=Data!G58,Data!F58,B2=Data!G59,Data!F59,B2=Data!G60,Data!F60,B2=Data!G61,Data!F61,B2=Data!G62,Data!F62,B2=Data!G63,Data!F63,B2=Data!G64,Data!F64,B2=Data!G65,Data!F65,B2=Data!G66,Data!F66,B2=Data!G67,Data!F67,B2="","")} -> R5SPE | C3: Team #: | H3: Base Code | I3: =B3 -> R5SPE | J3: Team #: | K3: =D3 -> 0
A4: Camp Name-BLD # | C4: System Voltage | H4: Camp Name-BLD # | I4: =B4 -> 0 | J4: System Voltage | K4: =D4 -> 0
A5: Building Type | C5: Inspection Phase | H5: Building Type | I5: =B5 -> 0 | J5: Inspection Phase | K5: =D5 -> 0
A6: Previous Report #: | H6: Previous Report #: | I6: =B6 -> 0
A7: Physical Building Location Description: | H7: Physical Building Location Description: | I7: =B7 -> 0
A8: MRF needed | C8: Overall Building Electrical | I8: Overall Building Electrical: | K8: =E8 -> 0
A9: Building Picture: | C9: Inspector Name: | H9: Building Picture: | J9: Inspector Name: | K9: =D9 -> 0
C10: Signed: | J10: Signed:
C12: Inspector Name: | J12: Inspector Name: | K12: =D12 -> 0
C13: Signed: | J13: Signed:
C15: QC Name: | J15: QC Name: | K15: =D15 -> 0
C16: Signed: | J16: Signed:
A18: LHS Deficiencies: | H18: Summary of Findings:
A19: Deficiency Number: | C19: =_xlfn.CONCAT("RAC"," ",'SOR Tracker'!N4) -> RAC | D19: Description of Deficiency Location:
C23: Number of Occurrences
C24: Deficiency Category :
C25: Equipment Category:
C26: Imminent Danger?
C27: If 'Yes' : Action Taken:
C28: SOR Issued To:
A29: Description of Deficiency:
A30: (or Mitigated State)
A31: Code Source: | C31: Deficiency Status:
A32: Code Reference:
A34: Deficiency Number: | B34: =B19+1 -> 1 | C34: =_xlfn.CONCAT("RAC"," ",'SOR Tracker'!N5) -> RAC | D34: Description of Deficiency Location:
C38: Number of Occurrences
C39: Deficiency Category :
C40: Equipment Category:
C41: Imminent Danger?
C42: If 'Yes' : Action Taken:
C43: SOR Issued To:
A44: Description of Deficiency:
A45: (or Mitigated State)
A46: Code Source: | C46: Deficiency Status:
A47: Code Reference:
A50: Deficiency Number: | B50: =B34+1 -> 2 | C50: =_xlfn.CONCAT("RAC"," ",'SOR Tracker'!N6) -> RAC | D50: Description of Deficiency Location:
C54: Number of Occurrences
C55: Deficiency Category :
...

Sheet SOR Tracker
A1: Inspection Report Number: | E1: ='Inspection Report'!A1 -> Re-Inspection-Report_TFSAFE_R5SPE___00-01-00_0 | O1: File Name:
A2: V32 | E2: Previous Report Number | I2: =IF('Inspection Report'!B6="","",'Inspection Report'!B6) | O2: V32
A3: Deficiency Number: | D3: Inspection phase | E3: Repair By | F3: Occurrences | G3: Imminent Danger | H3: O&M SOR # | I3: Repair Team # | J3: Parts Ordered | K3: Date Ordered | L3: Deficiency Status | M3: Date | N3: RAC | O3: MRF
A4: =_xlfn.CONCAT('Inspection Report'!B3,"_",'Inspection Report'!B4,"_",'Inspection Report'!D3,"_",TEXT('Inspection Report'!D2,"DD-MM-YY"),"_",'Inspection Report'!B19) -> R5SPE___00-01-00_ | B4: =IF('Inspection Report'!E24="","",'Inspection Report'!E24) | C4: =IF('Inspection Report'!E25="","",'Inspection Report'!E25) | D4: {=_xlfn.IFS('Inspection Report'!$D$5="Re Inspection","Re-Inspection",'Inspection Report'!$D$5="Full Inspection","Full Inspection",'Inspection Report'!$D$5="Callout","Callout")} -> #N/A | E4: =IF('Inspection Report'!E28="","",'Inspection Report'!E28) | F4: =IF($L$4=Data!E9,'Inspection Report'!$F$23,IF($L$4=Data!E10,'Inspection Report'!$F$23,IF($L$4=Data!E13,'Inspection Report'!$F$23,""))) | G4: =IF('Inspection Report'!E26="","",'Inspection Report'!E26) | L4: =IF('Inspection Report'!E31="","",'Inspection Report'!E31) | M4: =IF('Inspection Report'!E31="","",'Inspection Report'!$D$2) | N4: =Data!K31 | O4: ='Inspection Report'!B8 -> 0
A5: =_xlfn.CONCAT('Inspection Report'!B3,"_",'Inspection Report'!B4,"_",'Inspection Report'!D3,"_",TEXT('Inspection Report'!D2,"DD-MM-YY"),"_",'Inspection Report'!B34) -> R5SPE___00-01-00_1 | B5: =IF('Inspection Report'!E39="","",'Inspection Report'!E39) | C5: =IF('Inspection Report'!E40="","",'Inspection Report'!E40) | D5: {=_xlfn.IFS('Inspection Report'!$D$5="Re Inspection","Re-Inspection",'Inspection Report'!$D$5="Full Inspection","Full Inspection",'Inspection Report'!$D$5="Callout","Callout")} -> #N/A | E5: =IF('Inspection Report'!E43="","",'Inspection Report'!E43) | F5: =IF(L5=Data!$E$9,'Inspection Report'!$F$38,IF(L5=Data!$E$10,'Inspection Report'!$F$38,IF(L5=Data!$E$13,'Inspection Report'!$F$38,""))) | G5: =IF('Inspection Report'!E41="","",'Inspection Report'!E41) | L5: =IF('Inspection Report'!E46="","",'Inspection Report'!E46) | M5: =IF('Inspection Report'!E46="","",'Inspection Report'!$D$2) | N5: =Data!K32
A6: =_xlfn.CONCAT('Inspection Report'!B3,"_",'Inspection Report'!B4,"_",'Inspection Report'!D3,"_",TEXT('Inspection Report'!D2,"DD-MM-YY"),"_",'Inspection Report'!B50) -> R5SPE___00-01-00_2 | B6: =IF('Inspection Report'!E55="","",'Inspection Report'!E55) | C6: =IF('Inspection Report'!E56="","",'Inspection Report'!E56) | D6: {=_xlfn.IFS('Inspection Report'!$D$5="Re Inspection","Re-Inspection",'Inspection Report'!$D$5="Full Inspection","Full Inspection",'Inspection Report'!$D$5="Callout","Callout")} -> #N/A | E6: =IF('Inspection Report'!E59="","",'Inspection Report'!E59) | F6: =IF(L6=Data!$E$9,'Inspection Report'!F54,IF(L6=Data!$E$10,'Inspection Report'!F54,IF(L6=Data!$E$13,'Inspection Report'!F54,""))) | G6: =IF('Inspection Report'!E57="","",'Inspection Report'!E57) | L6: =IF('Inspection Report'!E62="","",'Inspection Report'!E62) | M6: =IF('Inspection Report'!E62="","",'Inspection Report'!$D$2) | N6: =Data!K33
A7: =_xlfn.CONCAT('Inspection Report'!B3,"_",'Inspection Report'!B4,"_",'Inspection Report'!D3,"_",TEXT('Inspection Report'!D2,"DD-MM-YY"),"_",'Inspection Report'!B65) -> R5SPE___00-01-00_3 | B7: =IF('Inspection Report'!E70="","",'Inspection Report'!E70) | C7: =IF('Inspection Report'!E71="","",'Inspection Report'!E71) | D7: {=_xlfn.IFS('Inspection Report'!$D$5="Re Inspection","Re-Inspection",'Inspection Report'!$D$5="Full Inspection","Full Inspection",'Inspection Report'!$D$5="Callout","Callout")} -> #N/A | E7: =IF('Inspection Report'!E74="","",'Inspection Report'!E74) | F7: =IF(L7=Data!$E$9,'Inspection Report'!F69,IF(L7=Data!$E$10,'Inspection Report'!$F$69,IF(L7=Data!$E$13,'Inspection Report'!$F$69,""))) | G7: =IF('Inspection Report'!E72="","",'Inspection Report'!E72) | L7: =IF('Inspection Report'!E77="","",'Inspection Report'!E77) | M7: =IF('Inspection Report'!E77="","",'Inspection Report'!$D$2) | N7: =Data!K34
A8: =_xlfn.CONCAT('Inspection Report'!B3,"_",'Inspection Report'!B4,"_",'Inspection Report'!D3,"_",TEXT('Inspection Report'!D2,"DD-MM-YY"),"_",'Inspection Report'!B80) -> R5SPE___00-01-00_4 | B8: =IF('Inspection Report'!E85="","",'Inspection Report'!E85) | C8: =IF('Inspection Report'!E86="","",'Inspection Report'!E86) | D8: {=_xlfn.IFS('Inspection Report'!$D$5="Re Inspection","Re-Inspection",'Inspection Report'!$D$5="Full Inspection","Full Inspection",'Inspection Report'!$D$5="Callout","Callout")} -> #N/A | E8: =IF('Inspection Report'!E89="","",'Inspection Report'!E89) | F8: =IF(L8=Data!$E$9,'Inspection Report'!$F$84,IF(L8=Data!$E$10,'Inspection Report'!$F$84,IF(L8=Data!$E$13,'Inspection Report'!$F$84,""))) | G8: =IF('Inspection Report'!E87="","",'Inspection Report'!E87) | L8: =IF('Inspection Report'!E92="","",'Inspection Report'!E92) | M8: =IF('Inspection Report'!E92="","",'Inspection Report'!$D$2) | N8: =Data!K35
A9: =_xlfn.CONCAT('Inspection Report'!B3,"_",'Inspection Report'!B4,"_",'Inspection Report'!D3,"_",TEXT('Inspection Report'!D2,"DD-MM-YY"),"_",'Inspection Report'!B97) -> R5SPE___00-01-00_5 | B9: =IF('Inspection Report'!E102="","",'Inspection Report'!E102) | C9: =IF('Inspection Report'!E103="","",'Inspection Report'!E103) | D9: {=_xlfn.IFS('Inspection Report'!$D$5="Re Inspection","Re-Inspection",'Inspection Report'!$D$5="Full Inspection","Full Inspection",'Inspection Report'!$D$5="Callout","Callout")} -> #N/A | E9: =IF('Inspection Report'!E106="","",'Inspection Report'!E106) | F9: =IF(L9=Data!$E$9,'Inspection Report'!$F$101,IF(L9=Data!$E$10,'Inspection Report'!$F$101,IF(L9=Data!$E$13,'Inspection Report'!$F$101,""))) | G9: =IF('Inspection Report'!E104="","",'Inspection Report'!E104) | L9: =IF('Inspection Report'!E109="","",'Inspection Report'!E109) | M9: =IF('Inspection Report'!E109="","",'Inspection Report'!$D$2) | N9: =Data!K36
A10: =_xlfn.CONCAT('Inspection Report'!B3,"_",'Inspection Report'!B4,"_",'Inspection Report'!D3,"_",TEXT('Inspection Report'!D2,"DD-MM-YY"),"_",'Inspection Report'!B112) -> R5SPE___00-01-00_6 | B10: =IF('Inspection Report'!E117="","",'Inspection Report'!E117) | C10: =IF('Inspection Report'!E118="","",'Inspection Report'!E118) | D10: {=_xlfn.IFS('Inspection Report'!$D$5="Re Inspection","Re-Inspection",'Inspection Report'!$D$5="Full Inspection","Full Inspection",'Inspection Report'!$D$5="Callout","Callout")} -> #N/A | E10: =IF('Inspection Report'!E121="","",'Inspection Report'!E121) | F10: =IF(L10=Data!$E$9,'Inspection Report'!$F$116,IF(L10=Data!$E$10,'Inspection Report'!$F$116,IF(L10=Data!$E$13,'Inspection Report'!$F$116,""))) | G10: =IF('Inspection Report'!E119="","",'Inspection Report'!E119) | L10: =IF('Inspection Report'!E124="","",'Inspection Report'!E124) | M10: =IF('Inspection Report'!E124="","",'Inspection Report'!$D$2) | N10: =Data!K37
A11: =_xlfn.CONCAT('Inspection Report'!B3,"_",'Inspection Report'!B4,"_",'Inspection Report'!D3,"_",TEXT('Inspection Report'!D2,"DD-MM-YY"),"_",'Inspection Report'!B127) -> R5SPE___00-01-00_7 | B11: =IF('Inspection Report'!E132="","",'Inspection Report'!E132) | C11: =IF('Inspection Report'!E133="","",'Inspection Report'!E133) | D11: {=_xlfn.IFS('Inspection Report'!$D$5="Re Inspection","Re-Inspection",'Inspection Report'!$D$5="Full Inspection","Full Inspection",'Inspection Report'!$D$5="Callout","Callout")} -> #N/A | E11: =IF('Inspection Report'!E136="","",'Inspection Report'!E136) | F11: =IF(L11=Data!$E$9,'Inspection Report'!$F$131,IF(L11=Data!$E$10,'Inspection Report'!$F$131,IF(L11=Data!$E$13,'Inspection Report'!$F$131,""))) | G11: =IF('Inspection Report'!E134="","",'Inspection Report'!E134) | L11: =IF('Inspection Report'!E139="","",'Inspection Report'!E139) | M11: =IF('Inspection Report'!E139="","",'Inspection Report'!$D$2) | N11: =Data!K38
A12: =_xlfn.CONCAT('Inspection Report'!B3,"_",'Inspection Report'!B4,"_",'Inspection Report'!D3,"_",TEXT('Inspection Report'!D2,"DD-MM-YY"),"_",'Inspection Report'!B144) -> R5SPE___00-01-00_8 | B12: =IF('Inspection Report'!E149="","",'Inspection Report'!E149) | C12: =IF('Inspection Report'!E150="","",'Inspection Report'!E150) | D12: {=_xlfn.IFS('Inspection Report'!$D$5="Re Inspection","Re-Inspection",'Inspection Report'!$D$5="Full Inspection","Full Inspection",'Inspection Report'!$D$5="Callout","Callout")} -> #N/A | E12: =IF('Inspection Report'!E153="","",'Inspection Report'!E153) | F12: =IF(L12=Data!$E$9,'Inspection Report'!$F$148,IF(L12=Data!$E$10,'Inspection Report'!$F$148,IF(L12=Data!$E$13,'Inspection Report'!$F$148,""))) | G12: =IF('Inspection Report'!E151="","",'Inspection Report'!E151) | L12: =IF('Inspection Report'!E156="","",'Inspection Report'!E156) | M12: =IF('Inspection Report'!E156="","",'Inspection Report'!$D$2) | N12: =Data!K39
A13: =_xlfn.CONCAT('Inspection Report'!B3,"_",'Inspection Report'!B4,"_",'Inspection Report'!D3,"_",TEXT('Inspection Report'!D2,"DD-MM-YY"),"_",'Inspection Report'!B159) -> R5SPE___00-01-00_9 | B13: =IF('Inspection Report'!E164="","",'Inspection Report'!E164) | C13: =IF('Inspection Report'!E165="","",'Inspection Report'!E165) | D13: {=_xlfn.IFS('Inspection Report'!$D$5="Re Inspection","Re-Inspection",'Inspection Report'!$D$5="Full Inspection","Full Inspection",'Inspection Report'!$D$5="Callout","Callout")} -> #N/A | E13: =IF('Inspection Report'!E168="","",'Inspection Report'!E168) | F13: =IF(L13=Data!$E$9,'Inspection Report'!$F$163,IF(L13=Data!$E$10,'Inspection Report'!$F$163,IF(L13=Data!$E$13,'Inspection Report'!$F$163,""))) | G13: =IF('Inspection Report'!E166="","",'Inspection Report'!E166) | L13: =IF('Inspection Report'!E171="","",'Inspection Report'!E171) | M13: =IF('Inspection Report'!E171="","",'Inspection Report'!$D$2) | N13: =Data!K40
A14: =_xlfn.CONCAT('Inspection Report'!B3,"_",'Inspection Report'!B4,"_",'Inspection Report'!D3,"_",TEXT('Inspection Report'!D2,"DD-MM-YY"),"_",'Inspection Report'!B174) -> R5SPE___00-01-00_10 | B14: =IF('Inspection Report'!E179="","",'Inspection Report'!E179) | C14: =IF('Inspection Report'!E180="","",'Inspection Report'!E180) | D14: {=_xlfn.IFS('Inspection Report'!$D$5="Re Inspection","Re-Inspection",'Inspection Report'!$D$5="Full Inspection","Full Inspection",'Inspection Report'!$D$5="Callout","Callout")} -> #N/A | E14: =IF('Inspection Report'!E183="","",'Inspection Report'!E183) | F14: =IF(L14=Data!$E$9,'Inspection Report'!$F$178,IF(L14=Data!$E$10,'Inspection Report'!$F$178,IF(L14=Data!$E$13,'Inspection Report'!$F$178,""))) | G14: =IF('Inspection Report'!E181="","",'Inspection Report'!E181) | L14: =IF('Inspection Report'!E186="","",'Inspection Report'!E186) | M14: =IF('Inspection Report'!E186="","",'Inspection Report'!$D$2) | N14: =Data!K41
A15: =_xlfn.CONCAT('Inspection Report'!B3,"_",'Inspection Report'!B4,"_",'Inspection Report'!D3,"_",TEXT('Inspection Report'!D2,"DD-MM-YY"),"_",'Inspection Report'!B191) -> R5SPE___00-01-00_11 | B15: =IF('Inspection Report'!E196="","",'Inspection Report'!E196) | C15: =IF('Inspection Report'!E197="","",'Inspection Report'!E197) | D15: {=_xlfn.IFS('Inspection Report'!$D$5="Re Inspection","Re-Inspection",'Inspection Report'!$D$5="Full Inspection","Full Inspection",'Inspection Report'!$D$5="Callout","Callout")} -> #N/A | E15: =IF('Inspection Report'!E200="","",'Inspection Report'!E200) | F15: =IF(L15=Data!$E$9,'Inspection Report'!$F$195,IF(L15=Data!$E$10,'Inspection Report'!$F$195,IF(L15=Data!$E$13,'Inspection Report'!$F$195,""))) | G15: =IF('Inspection Report'!E198="","",'Inspection Report'!E198) | L15: =IF('Inspection Report'!E203="","",'Inspection Report'!E203) | M15: =IF('Inspection Report'!E203="","",'Inspection Report'!$D$2) | N15: =Data!K42
A16: =_xlfn.CONCAT('Inspection Report'!B3,"_",'Inspection Report'!B4,"_",'Inspection Report'!D3,"_",TEXT('Inspection Report'!D2,"DD-MM-YY"),"_",'Inspection Report'!B206) -> R5SPE___00-01-00_12 | B16: =IF('Inspection Report'!E211="","",'Inspection Report'!E211) | C16: =IF('Inspection Report'!E212="","",'Inspection Report'!E212) | D16: {=_xlfn.IFS('Inspection Report'!$D$5="Re Inspection","Re-Inspection",'Inspection Report'!$D$5="Full Inspection","Full Inspection",'Inspection Report'!$D$5="Callout","Callout")} -> #N/A | E16: =IF('Inspection Report'!E215="","",'Inspection Report'!E215) | F16: =IF(L16=Data!$E$9,'Inspection Report'!$F$210,IF(L16=Data!$E$10,'Inspection Report'!$F$210,IF(L16=Data!$E$13,'Inspection Report'!$F$210,""))) | G16: =IF('Inspection Report'!E213="","",'Inspection Report'!E213) | L16: =IF('Inspection Report'!E218="","",'Inspection Report'!E218) | M16: =IF('Inspection Report'!E218="","",'Inspection Report'!$D$2) | N16: =Data!K43
A17: =_xlfn.CONCAT('Inspection Report'!B3,"_",'Inspection Report'!B4,"_",'Inspection Report'!D3,"_",TEXT('Inspection Report'!D2,"DD-MM-YY"),"_",'Inspection Report'!B221) -> R5SPE___00-01-00_13 | B17: =IF('Inspection Report'!E226="","",'Inspection Report'!E226) | C17: =IF('Inspection Report'!E227="","",'Inspection Report'!E227) | D17: {=_xlfn.IFS('Inspection Report'!$D$5="Re Inspection","Re-Inspection",'Inspection Report'!$D$5="Full Inspection","Full Inspection",'Inspection Report'!$D$5="Callout","Callout")} -> #N/A | E17: =IF('Inspection Report'!E230="","",'Inspection Report'!E230) | F17: =IF(L17=Data!$E$9,'Inspection Report'!$F$225,IF(L17=Data!$E$10,'Inspection Report'!$F$225,IF(L17=Data!$E$13,'Inspection Report'!$F$225,""))) | G17: =IF('Inspection Report'!E228="","",'Inspection Report'!E228) | L17: =IF('Inspection Report'!E233="","",'Inspection Report'!E233) | M17: =IF('Inspection Report'!E233="","",'Inspection Report'!$D$2) | N17: =Data!K44
A18: =_xlfn.CONCAT('Inspection Report'!B3,"_",'Inspection Report'!B4,"_",'Inspection Report'!D3,"_",TEXT('Inspection Report'!D2,"DD-MM-YY"),"_",'Inspection Report'!B238) -> R5SPE___00-01-00_14 | B18: =IF('Inspection Report'!E243="","",'Inspection Report'!E243) | C18: =IF('Inspection Report'!E244="","",'Inspection Report'!E244) | D18: {=_xlfn.IFS('Inspection Report'!$D$5="Re Inspection","Re-Inspection",'Inspection Report'!$D$5="Full Inspection","Full Inspection",'Inspection Report'!$D$5="Callout","Callout")} -> #N/A | E18: =IF('Inspection Report'!E247="","",'Inspection Report'!E247) | F18: =IF(L18=Data!$E$9,'Inspection Report'!$F$242,IF(L18=Data!$E$10,'Inspection Report'!$F$242,IF(L18=Data!$E$13,'Inspection Report'!$F$242,""))) | G18: =IF('Inspection Report'!E245="","",'Inspection Report'!E245) | L18: =IF('Inspection Report'!E250="","",'Inspection Report'!E250) | M18: =IF('Inspection Report'!E250="","",'Inspection Report'!$D$2) | N18: =Data!K45
A19: =_xlfn.CONCAT('Inspection Report'!B3,"_",'Inspection Report'!B4,"_",'Inspection Report'!D3,"_",TEXT('Inspection Report'!D2,"DD-MM-YY"),"_",'Inspection Report'!B253) -> R5SPE___00-01-00_15 | B19: =IF('Inspection Report'!E258="","",'Inspection Report'!E258) | C19: =IF('Inspection Report'!E259="","",'Inspection Report'!E259) | D19: {=_xlfn.IFS('Inspection Report'!$D$5="Re Inspection","Re-Inspection",'Inspection Report'!$D$5="Full Inspection","Full Inspection",'Inspection Report'!$D$5="Callout","Callout")} -> #N/A | E19: =IF('Inspection Report'!E262="","",'Inspection Report'!E262) | F19: =IF(L19=Data!$E$9,'Inspection Report'!$F$257,IF(L19=Data!$E$10,'Inspection Report'!$F$257,IF(L19=Data!$E$13,'Inspection Report'!$F$257,""))) | G19: =IF('Inspection Report'!E260="","",'Inspection Report'!E260) | L19: =IF('Inspection Report'!E265="","",'Inspection Report'!E265) | M19: =IF('Inspection Report'!E265="","",'Inspection Report'!$D$2) | N19: =Data!K46
A20: =_xlfn.CONCAT('Inspection Report'!B3,"_",'Inspection Report'!B4,"_",'Inspection Report'!D3,"_",TEXT('Inspection Report'!D2,"DD-MM-YY"),"_",'Inspection Report'!B268) -> R5SPE___00-01-00_16 | B20: =IF('Inspection Report'!E273="","",'Inspection Report'!E273) | C20: =IF('Inspection Report'!E274="","",'Inspection Report'!E274) | D20: {=_xlfn.IFS('Inspection Report'!$D$5="Re Inspection","Re-Inspection",'Inspection Report'!$D$5="Full Inspection","Full Inspection",'Inspection Report'!$D$5="Callout","Callout")} -> #N/A | E20: =IF('Inspection Report'!E277="","",'Inspection Report'!E277) | F20: =IF(L20=Data!$E$9,'Inspection Report'!$F$272,IF(L20=Data!$E$10,'Inspection Report'!$F$272,IF(L20=Data!$E$13,'Inspection Report'!$F$272,""))) | G20: =IF('Inspection Report'!E275="","",'Inspection Report'!E275) | L20: =IF('Inspection Report'!E280="","",'Inspection Report'!E280) | M20: =IF('Inspection Report'!E280="","",'Inspection Report'!$D$2) | N20: =Data!K47
A21: =_xlfn.CONCAT('Inspection Report'!B3,"_",'Inspection Report'!B4,"_",'Inspection Report'!D3,"_",TEXT('Inspection Report'!D2,"DD-MM-YY"),"_",'Inspection Report'!B285) -> R5SPE___00-01-00_17 | B21: =IF('Inspection Report'!E290="","",'Inspection Report'!E290) | C21: =IF('Inspection Report'!E291="","",'Inspection Report'!E291) | D21: {=_xlfn.IFS('Inspection Report'!$D$5="Re Inspection","Re-Inspection",'Inspection Report'!$D$5="Full Inspection","Full Inspection",'Inspection Report'!$D$5="Callout","Callout")} -> #N/A | E21: =IF('Inspection Report'!E294="","",'Inspection Report'!E294) | F21: =IF(L21=Data!$E$9,'Inspection Report'!$F$289,IF(L21=Data!$E$10,'Inspection Report'!$F$289,IF(L21=Data!$E$13,'Inspection Report'!$F$289,""))) | G21: =IF('Inspection Report'!E292="","",'Inspection Report'!E292) | L21: =IF('Inspection Report'!E297="","",'Inspection Report'!E297) | M21: =IF('Inspection Report'!E297="","",'Inspection Report'!$D$2) | N21: =Data!K48
A22: =_xlfn.CONCAT('Inspection Report'!B3,"_",'Inspection Report'!B4,"_",'Inspection Report'!D3,"_",TEXT('Inspection Report'!D2,"DD-MM-YY"),"_",'Inspection Report'!B300) -> R5SPE___00-01-00_18 | B22: =IF('Inspection Report'!E305="","",'Inspection Report'!E305) | C22: =IF('Inspection Report'!E306="","",'Inspection Report'!E306) | D22: {=_xlfn.IFS('Inspection Report'!$D$5="Re Inspection","Re-Inspection",'Inspection Report'!$D$5="Full Inspection","Full Inspection",'Inspection Report'!$D$5="Callout","Callout")} -> #N/A | E22: =IF('Inspection Report'!E309="","",'Inspection Report'!E309) | F22: =IF(L22=Data!$E$9,'Inspection Report'!$F$304,IF(L22=Data!$E$10,'Inspection Report'!$F$304,IF(L22=Data!$E$13,'Inspection Report'!$F$304,""))) | G22: =IF('Inspection Report'!E307="","",'Inspection Report'!E307) | L22: =IF('Inspection Report'!E312="","",'Inspection Report'!E312) | M22: =IF('Inspection Report'!E312="","",'Inspection Report'!$D$2) | N22: =Data!K49
A23: =_xlfn.CONCAT('Inspection Report'!B3,"_",'Inspection Report'!B4,"_",'Inspection Report'!D3,"_",TEXT('Inspection Report'!D2,"DD-MM-YY"),"_",'Inspection Report'!B315) -> R5SPE___00-01-00_19 | B23: =IF('Inspection Report'!E320="","",'Inspection Report'!E320) | C23: =IF('Inspection Report'!E321="","",'Inspection Report'!E321) | D23: {=_xlfn.IFS('Inspection Report'!$D$5="Re Inspection","Re-Inspection",'Inspection Report'!$D$5="Full Inspection","Full Inspection",'Inspection Report'!$D$5="Callout","Callout")} -> #N/A | E23: =IF('Inspection Report'!E324="","",'Inspection Report'!E324) | F23: =IF(L23=Data!$E$9,'Inspection Report'!$F$319,IF(L23=Data!$E$10,'Inspection Report'!$F$319,IF(L23=Data!$E$13,'Inspection Report'!$F$319,""))) | G23: =IF('Inspection Report'!E322="","",'Inspection Report'!E322) | L23: =IF('Inspection Report'!E327="","",'Inspection Report'!E327) | M23: =IF('Inspection Report'!E327="","",'Inspection Report'!$D$2) | N23: =Data!K50

Sheet Cover Sheet

Sheet Cover Note

Sheet Data
D1: Building Type | E1: Inspection Phase | F1: Base Code | G1: Description | H1: Country | J1: System Voltage
B2: Yes | C2: 3.5
B3: No | C3: 0.5 | D3: LSAU | E3: Full Inspection | F3: H4QXY | G3: Camp Arifjan | H3: Kuwait | J3: 230/400 | K3: BritishStandard | P3: =B2 -> Yes | Q3: =B3 -> No | U3: Full Inspection | V3: Re Inspection | W3: Callout | AA3: Full Inspection | AB3: Re Inspection
B4: N/A | D4: Medical Facility | E4: Re-Inspection | F4: R5SPE | G4: Camp Buehring | H4: Kuwait | J4: 120/208 | K4: NEC | P4: Repaired | Q4: N/A | U4: Open | V4: Open | W4: Open | AA4: Task Force SAFE | AB4: Task Force SAFE
D5: DFAC | E5: Call-Out | F5: SMMAD | G5: AMOD | H5: Kuwait | J5: 277/480 | K5: NEC | P5: Mitigated | U5: Closed / Repaired | V5: Closed / Repaired | W5: Closed / Repaired | AA5: O&M Provider | AB5: O&M Provider
B6: Repaired | D6: Billeting | F6: S6CYH | G6: Ali Al Salem Air Base | H6: Kuwait | J6: Hybrid/Combo | V6: Closed Previously | AA6: Military | AB6: Military
B7: Mitigated | D7: Office | E7: Deficiency Status | F7: 446PD | G7: KNB | H7: Kuwait | V7: ReInsp-Open
B8: N/A | D8: Retail | F8: SPART | G8: Sparta | H8: Kuwait | V8: TFS Closed
D9: MWR/USO | E9: Open | F9: 9R7UA | G9: SPOD | H9: Kuwait
B10: Task Force SAFE | D10: Electrical Distro | E10: Closed / Repaired | F10: EURGL | G10: Camp KASOTC | H10: Jordan
B11: O&M Provider | D11: Other | E11: Closed Previously | F11: 5VN8M | G11: JTC | H11: Jordan
B12: Military | E12: ReInsp-Open | F12: CTP5R | G12: PHRB | H12: Jordan
D13: Equipment Category | E13: TFS Closed | F13: 969ZA | G13: MSAB | H13: Jordan | AA13: Task Force SAFE | AB13: O&M Provider | AC13: Military
F14: 7NX32 | G14: H-5 | H14: Jordan | M14: RAC
B15: Deficiency Category | D15: WLT | F15: LTRYC | G15: HTC | H15: Jordan | M15: 1
D16: CDP | F16: GCP23 | G16: Titin | H16: Jordan | M16: 2
B17: Grounding and Bonding | C17: 2.5 | D17: MDP | F17: CP2FL | G17: Tower 22 | H17: Jordan | M17: 3 | U17: Re Inspection | V17: TFS Closed
B18: Improper Terminations | C18: 1 | D18: GEN | F18: 75KR8 | G18: New JTC | H18: Jordan | M18: 4
B19: Improper Use / Damaged | C19: 2 | D19: TR | F19: JAVRH | G19: Azraq Air Base | H19: Jordan
B20: Poor Workmanship | C20: 1 | D20: ATS | F20: 8AD6R | G20: Badger | H20: Jordan | V20: {=INDIRECT(SUBSTITUTE(U17," ","_"))} -> Open
B21: Unlisted Equipment | C21: 2 | D21: MTS | F21: 1T4JI | G21: Taji | H21: Iraq | V21: Closed / Repaired
D22: SDP | F22: F797V | G22: Erbil | H22: Iraq | V22: Closed Previously
F23: KIRKU | G23: Kirkuk | H23: Iraq | V23: ReInsp-Open
F24: QWEST | G24: Qwest | H24: Iraq | V24: TFS Closed
F25: XZ722 | G25: Al Asad | H25: Iraq
B26: Good | C26: 0 | F26: 2R6S8 | G26: Baghdad Diplomatic Support Center | H26: Iraq
B27: Fair | C27: 0 | F27: LSCNF | G27: EIA | H27: Iraq
B28: Poor | C28: 0.5 | F28: BXPEZ | G28: CTSOTF | H28: Iraq
F29: EYVPF | G29: MARSOC | H29: Iraq
F30: B62XQ | G30: Candians | H30: Iraq | I30: DEF# | J30: RISK Score | K30: RAC | U30: Filename
F31: TQIRA | G31: TQ | H31: Iraq | I31: 1 | J31: =SUMIF(Data!$B$2:$B$3,'Inspection Report'!E26,Data!$C$2:$C$3)+SUMIF(Data!$B$17:$B$21,'Inspection Report'!E24,Data!$C$17:$C$21)+SUMIF(Data!B26:B28,'Inspection Report'!E8,Data!C26:C28) -> 0 | K31: =IF(J31>=4,$M$15,IF(J31>=2,$M$16,IF(J31>=1,$M$17,""))) | U31: First Def # | V31: ='Inspection Report'!B19 -> 0
F32: MANIO | G32: Camp Manion, TQ | H32: Iraq | I32: 2 | J32: =SUMIF(Data!$B$2:$B$3,'Inspection Report'!E41,Data!$C$2:$C$3)+SUMIF(Data!$B$17:$B$21,'Inspection Report'!E39,Data!$C$17:$C$21)+SUMIF(Data!B26:B28,'Inspection Report'!E8,Data!C26:C28) -> 0 | K32: =IF(J32>=4,$M$15,IF(J32>=2,$M$16,IF(J32>=1,$M$17,""))) | U32: Last Def # | V32: =_xlfn.CONCAT(V34,V36)
F33: A1QUM | G33: Al Qa'im | H33: Iraq | I33: 3 | J33: =SUMIF(Data!$B$2:$B$3,'Inspection Report'!E57,Data!$C$2:$C$3)+SUMIF(Data!$B$17:$B$21,'Inspection Report'!E55,Data!$C$17:$C$21)+SUMIF(Data!B26:B28,'Inspection Report'!E8,Data!C26:C28) -> 0 | K33: =IF(J33>=4,$M$15,IF(J33>=2,$M$16,IF(J33>=1,$M$17,""))) | U33: Number of additional Defs | V33: =(COUNTIF('SOR Tracker'!M4:M23,">0")-1) -> -1
F34: NOC-E | G34: NOC-E | H34: Iraq | I34: 4 | J34: =SUMIF(Data!$B$2:$B$3,'Inspection Report'!E72,Data!$C$2:$C$3)+SUMIF(Data!$B$17:$B$21,'Inspection Report'!E70,Data!$C$17:$C$21)+SUMIF(Data!B26:B28,'Inspection Report'!E8,Data!C26:C28) -> 0 | K34: =IF(J34>=4,$M$15,IF(J34>=2,$M$16,IF(J34>=1,$M$17,""))) | V34: =IF(V33>0,"-","")
F35: THERA | G35: The Ranch, TQ | H35: Iraq | I35: 5 | J35: =SUMIF(Data!$B$2:$B$3,'Inspection Report'!E87,Data!$C$2:$C$3)+SUMIF(Data!$B$17:$B$21,'Inspection Report'!E85,Data!$C$17:$C$21)+SUMIF(Data!B26:B28,'Inspection Report'!E8,Data!C26:C28) -> 0 | K35: =IF(J35>=4,$M$15,IF(J35>=2,$M$16,IF(J35>=1,$M$17,""))) | V35: =IF(V33>0,V33,"")
F36: A88T2 | G36: KSB | H36: Iraq | I36: 6 | J36: =SUMIF(Data!$B$2:$B$3,'Inspection Report'!E104,Data!$C$2:$C$3)+SUMIF(Data!$B$17:$B$21,'Inspection Report'!E102,Data!$C$17:$C$21)+SUMIF(Data!B26:B28,'Inspection Report'!E8,Data!C26:C28) -> 0 | K36: =IF(J36>=4,$M$15,IF(J36>=2,$M$16,IF(J36>=1,$M$17,""))) | U36: 1st def 3# & # of defs | V36: =IF(V33>0,V31+V33,"")
F37: P9P4U | G37: Al Riffa Air Base | H37: Bahrain | I37: 7 | J37: =SUMIF(Data!$B$2:$B$3,'Inspection Report'!E119,Data!$C$2:$C$3)+SUMIF(Data!$B$17:$B$21,'Inspection Report'!E117,Data!$C$17:$C$21)+SUMIF(Data!B26:B28,'Inspection Report'!E8,Data!C26:C28) -> 0 | K37: =IF(J37>=4,$M$15,IF(J37>=2,$M$16,IF(J37>=1,$M$17,"")))
F38: 69FKG | G38: Isa Air Base | H38: Bahrain | I38: 8 | J38: =SUMIF(Data!$B$2:$B$3,'Inspection Report'!E134,Data!$C$2:$C$3)+SUMIF(Data!$B$17:$B$21,'Inspection Report'!E132,Data!$C$17:$C$21)+SUMIF(Data!B26:B28,'Inspection Report'!E8,Data!C26:C28) -> 0 | K38: =IF(J38>=4,$M$15,IF(J38>=2,$M$16,IF(J38>=1,$M$17,"")))
F39: CASAB | G39: CAS Air Base | H39: Qatar | I39: 9 | J39: =SUMIF(Data!$B$2:$B$3,'Inspection Report'!E151,Data!$C$2:$C$3)+SUMIF(Data!$B$17:$B$21,'Inspection Report'!E149,Data!$C$17:$C$21)+SUMIF(Data!B26:B28,'Inspection Report'!E8,Data!C26:C28) -> 0 | K39: =IF(J39>=4,$M$15,IF(J39>=2,$M$16,IF(J39>=1,$M$17,"")))
F40: CASSO | G40: CAS South | H40: Qatar | I40: 10 | J40: =SUMIF(Data!$B$2:$B$3,'Inspection Report'!E166,Data!$C$2:$C$3)+SUMIF(Data!$B$17:$B$21,'Inspection Report'!E164,Data!$C$17:$C$21)+SUMIF(Data!B26:B28,'Inspection Report'!E8,Data!C26:C28) -> 0 | K40: =IF(J40>=4,$M$15,IF(J40>=2,$M$16,IF(J40>=1,$M$17,"")))
...
